Workbook

Sheet 한국은행보고서_Sample
A1: 취급점포코드 | B1: 취급점포소재지 | C1: 전송구분 | D1: 상품코드 | E1: 체결번호 | F1: 매입업체코드 | G1: 매도업체코드 | H1: 금액 | I1: 기준통화코드 | J1: 상대통화코드 | K1: 체결시각 | L1: 장내/장외 | M1: 결제일 | N1: 시작일 | O1: 종료일 | P1: 행사만기일 | Q1: 기일코드 | R1: 거래환율 | S1: 근일물 거래환율 | T1: 원일물 거래환율 | U1: 시장평균환율 대비 가감율 | V1: 고정금리 | W1: 중개사 거래 변동금리 코드 | X1: 변동금리 | Y1: Put/Call | Z1: Type | AA1: 옵션가격(달러화)
A2: 1 | B2: 04542. | C2: 1 | D2: 11 | E2: =RIGHT('FX_DEAL All'!E2,5) -> 00107 | F2: 1188 | G2: 1104 | H2: 29358000 | I2: AUD | J2: AUD | K2: 164043 | L2: 1 | N2: 20240419 | O2: 20240520 | R2: 1187.2 | U2: 0 | V2: 2.92
A3: 1 | B3: 04542. | C3: 1 | D3: 11 | E3: =RIGHT('FX_DEAL All'!E3,5) -> 00207 | F3: 1104 | G3: 1188 | H3: 51257643 | I3: CAD | J3: CAD | K3: 164320 | L3: 1 | N3: 20240419 | O3: 20240721 | R3: 1187.2 | U3: 0 | V3: 2.1
A4: 1 | B4: 04542. | C4: 1 | D4: 11 | E4: =RIGHT('FX_DEAL All'!E4,5) -> 00307 | F4: 1331 | G4: 1560 | H4: 2.0655e+08 | I4: CNH | J4: CNH | K4: 144645 | L4: 1 | N4: 20240403 | O4: 20240404 | R4: 1187.2 | U4: 0 | V4: 2.2255
A5: 1 | B5: 04542. | C5: 1 | D5: 11 | E5: =RIGHT('FX_DEAL All'!E5,5) -> 00407 | F5: 1560 | G5: 1331 | H5: 19314000 | I5: EUR | J5: EUR | K5: 171340 | L5: 1 | N5: 20240419 | O5: 20240620 | R5: 1187.2 | U5: 0 | V5: -0.12
A6: 1 | B6: 04542. | C6: 1 | D6: 11 | E6: =RIGHT('FX_DEAL All'!E6,5) -> 00507 | F6: 1544 | G6: 1403 | H6: 65059800 | I6: GBP | J6: GBP | K6: 172121 | L6: 1 | N6: 20240417 | O6: 20240418 | R6: 1187.2 | U6: 0 | V6: 0.15
A7: 1 | B7: 04542. | C7: 1 | D7: 11 | E7: =RIGHT('FX_DEAL All'!E7,5) -> 00607 | F7: 1403 | G7: 1544 | H7: 2235693.2 | I7: HKD | J7: HKD | K7: 172708 | L7: 1 | N7: 20240417 | O7: 20240418 | R7: 1187.2 | U7: 0 | V7: 0.15
A8: 1 | B8: 04542. | C8: 1 | D8: 11 | E8: =RIGHT('FX_DEAL All'!E8,5) -> 00707 | F8: 1519 | G8: 1521 | H8: 19282064 | I8: JPY | J8: JPY | K8: 174556 | L8: 1 | N8: 20240417 | O8: 20240418 | R8: 1187.2 | U8: 0 | V8: 0.15
A9: 1 | B9: 04542. | C9: 1 | D9: 11 | E9: =RIGHT('FX_DEAL All'!E9,5) -> 00807 | F9: 1521 | G9: 1519 | H9: 11916000 | I9: NZD | J9: NZD | K9: 174749 | L9: 1 | N9: 20240417 | O9: 20240418 | R9: 1187.2 | U9: 0 | V9: 2.5
A10: 1 | B10: 04542. | C10: 1 | D10: 11 | E10: =RIGHT('FX_DEAL All'!E10,5) -> 00907 | F10: 1331 | G10: 1104 | H10: 25758022 | I10: SGD | J10: SGD | K10: 180536 | L10: 1 | N10: 20240419 | O10: 20240422 | R10: 1187.2 | U10: 0 | V10: 1.1
A11: 1 | B11: 04542. | C11: 1 | D11: 11 | E11: =RIGHT('FX_DEAL All'!E11,5) -> 01007 | F11: 1104 | G11: 1331 | H11: 100000000 | I11: USD | J11: USD | K11: 111618 | L11: 1 | N11: 20240403 | O11: 20240404 | R11: 1187.2 | U11: 0 | V11: 5.6
A12: 1 | B12: 04542. | C12: 1 | D12: 31 | E12: =RIGHT('FX_DEAL All'!E12,5) -> 00105 | F12: 1519 | G12: 1544 | H12: 50000000 | I12: USD | J12: KRW | K12: 103555 | L12: 1 | M12: 20240715 | Q12: 51 | R12: 1184.485
A13: 1 | B13: 04542. | C13: 1 | D13: 33 | E13: =RIGHT('FX_DEAL All'!E13,5) -> 00301 | F13: 1544 | G13: 1519 | H13: 1.1122233e+08 | I13: USD | J13: KRW | K13: 174140 | L13: 1 | N13: 20240604 | O13: 20240705 | Q13: 61 | S13: 1186.8 | T13: 1186.5
A14: 1 | B14: 04542. | C14: 1 | D14: 33 | E14: =RIGHT('FX_DEAL All'!E14,5) -> 01101 | F14: 1104 | G14: 1521 | H14: 72642743 | I14: USD | J14: KRW | K14: 180639 | L14: 1 | N14: 20240405 | O14: 20240507 | Q14: 61 | S14: 1186.8 | T14: 1186.5
A15: 1 | B15: 04542. | C15: 1 | D15: 33 | E15: =RIGHT('FX_DEAL All'!E15,5) -> 01201 | F15: 1104 | G15: 1521 | H15: 94424000 | I15: USD | J15: KRW | K15: 180639 | L15: 1 | N15: 20240405 | O15: 20240507 | Q15: 04 | S15: 1188.7 | T15: 1188.73
A16: 1 | B16: 04542. | C16: 1 | D16: 33 | E16: =RIGHT('FX_DEAL All'!E16,5) -> 01301 | F16: 1519 | G16: 1560 | H16: 67562100 | I16: USD | J16: KRW | K16: 180639 | L16: 1 | N16: 20240405 | O16: 20240507 | Q16: 04 | S16: 1188.9 | T16: 1188.93
A17: 1 | B17: 04542. | C17: 1 | D17: 33 | E17: =RIGHT('FX_DEAL All'!E17,5) -> 01401 | F17: 1560 | G17: 1519 | H17: 12775389 | I17: USD | J17: KRW | K17: 180639 | L17: 1 | N17: 20240405 | O17: 20240507 | Q17: 06 | S17: 1186.7 | T17: 1186.72
A18: 1 | B18: 04542. | C18: 1 | D18: 33 | E18: =RIGHT('FX_DEAL All'!E18,5) -> 01501 | F18: 1403 | G18: 1331 | H18: 2754000000 | I18: USD | J18: KRW | K18: 180639 | L18: 1 | N18: 20240405 | O18: 20240507 | Q18: 06 | S18: 1186.7 | T18: 1186.72
A19: 1 | B19: 04542. | C19: 1 | D19: 33 | E19: =RIGHT('FX_DEAL All'!E19,5) -> 01161 | F19: 1331 | G19: 1403 | H19: 19282064 | I19: USD | J19: KRW | K19: 180639 | L19: 1 | N19: 20240405 | O19: 20240507 | Q19: 06 | S19: 1186.7 | T19: 1186.72
A20: 1 | B20: 04542. | C20: 1 | D20: 32 | E20: =RIGHT('FX_DEAL All'!E20,5) -> 00104 | F20: 1544 | G20: 1519 | H20: 50000000 | I20: USD | J20: KRW | K20: 103646 | L20: 1 | M20: 20240715 | Q20: 06 | S20: 1186.7 | T20: 1186.72
A21: 1 | B21: 04542. | C21: 1 | D21: 32 | E21: =RIGHT('FX_DEAL All'!E21,5) -> 00106 | F21: 1519 | G21: 1544 | H21: 1.1122233e+08 | I21: USD | J21: KRW | K21: 152146 | L21: 1 | M21: 20240517 | Q21: 33 | S21: 1186.2 | T21: 1185.95
A22: 1 | B22: 04542. | C22: 1 | D22: 34 | E22: =RIGHT('FX_DEAL All'!E22,5) -> 00102 | F22: 1544 | G22: 1104 | H22: 1e+08 | I22: USD | J22: KRW | K22: 145455 | L22: 1 | N22: 20240507 | O22: 20240805 | Q22: 31 | S22: 1186.2 | T22: 1186.2
A23: 1 | B23: 04542. | C23: 1 | D23: 22 | E23: =RIGHT('FX_DEAL All'!E23,5) -> 00103 | F23: 1104 | G23: 1544 | H23: 1250000.2 | I23: USD | J23: KRW | K23: 145610 | L23: 1 | M23: 20240405 | Q23: 51 | S23: 1186.3 | T23: 1184
A24: 1 | B24: 04542. | C24: 1 | D24: 22 | E24: =RIGHT('FX_DEAL All'!E24,5) -> 00303 | F24: 1521 | G24: 1403 | H24: 50000000 | I24: USD | J24: KRW | K24: 171509 | L24: 1 | M24: 20240411 | Q24: 04 | S24: 1187.2 | T24: 1187.22
A25: 1 | B25: 04542. | C25: 1 | D25: 22 | E25: =RIGHT('FX_DEAL All'!E25,5) -> 01103 | F25: 1403 | G25: 1521 | H25: 5000000 | I25: USD | J25: KRW | K25: 104023 | L25: 1 | M25: 20240415 | Q25: 33 | S25: 1187.2 | T25: 1186.95
A26: 1 | B26: 04542. | C26: 1 | D26: 35 | E26: 00133 | F26: 1104 | G26: 1331 | H26: 23000000 | I26: USD | J26: KRW | K26: 124425 | L26: 1 | N26: 20240429 | O26: 20390429 | R26: 1301.02 | V26: 2.88525 | W26: 10 | X26: 0
A27: 1 | B27: 04542. | C27: 1 | D27: 45 | E27: 00155 | F27: 1331 | G27: 1104 | H27: 14528549 | I27: KRW | J27: KRW | K27: 131700 | L27: 1 | N27: 20240425 | O27: 20270426 | V27: 3.05 | W27: 03 | X27: 0
A28: 1 | B28: 04542. | C28: 1 | D28: 41 | E28: 00111 | F28: 1403 | G28: 1544 | H28: 36321371 | I28: KRW | J28: KRW | K28: 92744 | L28: 1 | N28: 20240426 | O28: 20270426 | V28: 3.53 | W28: 03 | X28: 0
A29: 1 | B29: 04542. | C29: 1 | D29: 42 | E29: 01211 | F29: 1544 | G29: 1403 | H29: 20000000 | I29: USD | J29: USD | K29: 92708 | L29: 1 | N29: 20240426 | O29: 20270426 | V29: 3.53 | W29: 11 | X29: 0
A30: 1 | B30: 04542. | C30: 1 | D30: 36 | E30: 00144 | F30: 1521 | G30: 1403 | H30: 10000000 | I30: USD | J30: KRW | K30: 122211 | L30: 1 | N30: 20240429 | O30: 20270429 | R30: 1387 | V30: 2.78 | W30: 10 | X30: 0
A31: 1 | B31: 04542. | C31: 1 | D31: 45 | E31: 00266 | F31: 1403 | G31: 1521 | H31: 50000000 | I31: USD | J31: USD | K31: 133003 | L31: 1 | N31: 20240425 | O31: 20270426 | V31: 3.05 | W31: 11 | X31: 0
A32: 1 | B32: 04542. | C32: 1 | D32: 41 | E32: 00422 | F32: 1188 | G32: 1519 | H32: 10896411 | I32: KRW | J32: KRW | K32: 125502 | L32: 1 | N32: 20240426 | O32: 20360428 | V32: 2.9875 | W32: 03 | X32: 0
A33: 1 | B33: 04542. | C33: 1 | D33: 44 | E33: 00177 | F33: 1519 | G33: 1188 | H33: 14528549 | I33: KRW | J33: KRW | K33: 105001 | L33: 1 | P33: 20270426 | V33: 2.9
A34: 1 | B34: 04542. | C34: 1 | D34: 44 | E34: 00277 | F34: 1188 | G34: 1519 | H34: 35000000 | I34: USD | J34: USD | K34: 105033 | L34: 1 | P34: 20270426 | V34: 2.9

Sheet 레이아웃 설명
A1: FX0074 | C1: 한국은행보고서명 FX0074 샘플로 작성 노란색 내용- FX 딜승인조회화면에서 "FX DEAL ALL" 내역 기반으로 작성 초록색 내용- IRS 딜승인조회화면에서 "IRS DEAL ALL" 내역 기반으로 작성 (FXIRS DEAL ALL 내역에서 필요한값의 열만 색상 표시) | G1: 보고서명 | H1: 중개사 경유 외환 및 파생상품거래내역
G2: 업무담당 | H2: 한국은행 외환시장팀(☎759-5916)
G3: 근거규정 | H3: 외국환거래규정 제3-4조
G4: 작성기관 | H4: 외국환중개회사
G5: 보고개요 | H5: 보고점포그룹구분 : 본점일반(1) / 보고주기 및 시한 : 일보(익영업일 11시)
A6: NO | B6: 항 목 | C6: 보고서 엑셀위치 | D6: 적용 내용 | E6: 추가설명 | G6: 속성 | H6: 길이 | I6: 필수 | J6: KEY항목 여부 | K6: 분석 항목명 | L6: 비 고
A7: 1 | B7: 보고기관코드 | C7: X | D7: X | E7: X | G7: X(4) | H7: 4 | I7: M | J7: Y | K7: (CODE 1)
A8: 2 | B8: 취급점포코드 | C8: X | D8: X | E8: X | G8: X(4) | H8: 4 | I8: M | J8: N | L8: 은행 : 금융공동망코드의 마지막 4자리, 기타 : 자체 관리 점포코드 4자리
A9: 5 | B9: 전송일자 | C9: X | D9: X | E9: X | G9: X(8) | H9: 8 | I9: X | J9: Y | L9: YYYYMMDD
A10: 6 | B10: 작성기준일자 | C10: X | D10: X | E10: X | G10: X(8) | H10: 8 | I10: M | J10: Y | L10: 체결일자, YYYYMMDD
A11: 7 | B11: 전송횟수 | C11: X | D11: X | E11: X | G11: X(2) | H11: 2 | I11: X | J11: Y | L11: 한국은행 시스템에서 자동부여
A12: 9 | B12: 처리번호 | C12: X | D12: X | E12: X | G12: X(6) | H12: 6 | I12: X | J12: N | L12: 한국은행 시스템에서 자동부여
A13: 4 | B13: 보고점포그룹구분코드 | C13: A열 | D13: 1 | E13: "1" 디폴트 | G13: X(1) | H13: 1 | I13: M | J13: Y | K13: (CODE 211)
A14: 3 | B14: 취급점포소재지식별번호 | C14: B열 | D14: 04542. | E14: 04542. 값 디폴트 | G14: X(6) | H14: 6 | I14: M | J14: N | L14: 국내: 우편번호, 국외: BIC CODE 5~8번째자리 예)CZNBKRSEXXX
A15: 8 | B15: 전송구분코드 | C15: C열 | D15: 1 | E15: "1" 디폴트 (2.3번 삭제. 수정은 수작업처리) | G15: X(1) | H15: 1 | I15: M | J15: Y | K15: (CODE 195) | L15: 1:신규(Insert), 2:삭제(Delete), 4:수정(Update)
A16: 10 | B16: 상품구분코드 | C16: D열 | D16: 2자리 | E16: [11] DEPOSIT [22] SPOT MAR [31] DF [32] NDF & ND MAR [33] FX SWAP [34] ND SWAP [35] CRS [36] ND CRS [41] IRS-KRW & ND IRS-KRW [42] IRS-USD & & ND IRS-USD [45] FRA & ND FRA [44] SWAPTION ** (ND) IRS 중에서 거래통화 KRW와 USD 상품코드가 상이** | G16: X(2) | H16: 2 | I16: M | J16: Y | K16: CODE 추가 (1:중개사 상품구분) (CODE 2350) | L16: 11. 자금, 21. 현물환, 22. Average Price FX, 31. 통화선도(차액결제제외), 32. 통화선도(차액결제), 33. 외환스왑(차액결제제외), 34. 외환스왑(차액결제), 35. 통화스왑(차액결제제외), 36. 통화스왑(차액결제), 37. 통화옵션, 41. 이자율스왑(원화), 42. 이자율스왑(외화), 43. OIS스왑,44. 이자율옵션, 45. FRA
A17: 11 | B17: 체결번호 | C17: E열 | D17: 5자리 | E17: FX. IRS REFERENCE NO. 뒤에서 5자리 사용 | G17: 9(5) | H17: 5 | I17: M | J17: Y
A18: 12 | B18: 매입기관코드 | C18: F열 | D18: 4자리 | E18: *FX SWAP, ND SWAP, SPOT MAR, NDF, DF, ND MAR* BUYER 은행코드 앞 4자리 예외: FX SWAP_CCY Pair_KRW/USD 인 경우 SELLER 4자리 **DEPOSIT** Borrower 은행코드 앞 4자리 *IRS, ND IRS, CRS, ND CRS, FRA, ND FRA, SWAPTION* PAY 은행코드 앞 4자리 | G18: X(4) | H18: 4 | I18: M | J18: N | K18: (CODE 410) | L18: ■ '11. 자금'의 경우, 자금을 차입하는 기관이 매입기관 ■ '33. 외환스왑(차액결제제외), 34. 외환스왑(차액결제), 35. 통화스왑(차액결제제외), 36. 통화스왑(차액결제)'의 경우 원일물거래를 기준으로 보고(sell&buy, CRS pay한 경우 매입기관)하되, 원화미게재거래(외화간거래)의 경우 기준통화를 기준으로 보고(예: EUR-USD간 외환스왑의 경우 EUR를 Sell&Buy한 기관이 매입기관) ■ '41. 이자율스왑(원화), 42. 이자율스왑(외화)'의 경우 고정금리 지급기관이 매입기관
A19: 13 | B19: 매도기관코드 | C19: G열 | D19: 4자리 | E19: *FX SWAP, ND SWAP, SPOT MAR, NDF, DF, ND MAR* SELLER 은행코드 앞 4자리 예외: FX SWAP_CCY Pair_KRW/USD 인 경우 BUYER 4자리 **DEPOSIT** Lender 은행코드 앞 4자리 *IRS, ND IRS, CRS, ND CRS, FRA, ND FRA, SWAPTION* RECEIVE 은행코드 앞 4자리 | G19: X(4) | H19: 4 | I19: M | J19: N | K19: (CODE 410) | L19: ■ '11. 자금'의 경우, 자금을 차입하는 기관이 매입기관 ■ '33. 외환스왑(차액결제제외), 34. 외환스왑(차액결제), 35. 통화스왑(차액결제제외), 36. 통화스왑(차액결제)'의 경우 원일물거래를 기준으로 보고(sell&buy, CRS pay한 경우 매입기관)하되, 원화미게재거래(외화간거래)의 경우 기준통화를 기준으로 보고(예: EUR-USD간 외환스왑의 경우 EUR를 Sell&Buy한 기관이 매입기관) ■ '41. 이자율스왑(원화), 42. 이자율스왑(외화)'의 경우 고정금리 지급기관이 매입기관
A20: 14 | B20: 금액 | C20: H열 | D20: 모든 통화 USD로 환산한 AMOUNT | E20: FX.IRS 딜 조회 승인화면 DEAL ALL 내역상 CCY PAIR 앞 3자리가 1. "USD"일 경우: 그대로 사용. 2. "KRW"일 경우: TRADE DATE의 기준환율(Base Rate)로 나누기. 3. "그외 ccy"일 경우: Exchange Rate 화면_해당통화 Cross Rate로 나누거나 곱하기. **곱해야하는 CCY: EUR,AUD,GBP,NZD,CNH **나눠야하는 CCY: SGD,HKD,JPY,CAD,CHF,NOK,SEK,DKK,THB,AED | G20: S9(15,2) | H20: 16 | I20: M | J20: N | L20: 단위 : USD (기타통화는 USD환산금액) ■ '33. 외환스왑(차액결제제외), 34. 외환스왑(차액결제)'의 경우 근일물거래금액을 입력 ■ '37. 통화옵션, 44. 이자율옵션'의 경우 옵션프리미엄이 아닌 명목금액을 입력
A21: 15 | B21: 기준통화코드 | C21: I열 | D21: 3자리 | E21: [FX SWAP, ND SWAP, SPOT MAR, NDF, DF, ND MAR] "USD" 디폴트 [DEPOSIT] CCY pair 있는 그대로 사용 [IRS, ND IRS, CRS, ND CRS, FRA, ND FRA, SWAPTION] CCY pair 앞 3자리 | G21: X(3) | H21: 3 | I21: M | J21: N | K21: (CODE 18) | L21: ■ '11. 자금'의 경우, 거래되는 해당 통화를 동일하게 기입 ■ 일반적으로 2개의 통화를 교환하는 모든 외환상품에서는 EUR GBP AUD NZD USD JPY CNH KRW 등의 순서에 따라 앞에 오는 것을 기준통화(base currency)로, 뒤에 오는 것을 상대통화(counter currency)로 분류. (기준통화코드에 USD가 오지 않는 경우에 유의) ex. (기준/상대) : EUR/USD, EUR/GBP, GBP/USD, USD/JPY, JPY/KRW, USD/KRW 등 ■ 외국통화가 수반되지 않는 원화거래(예: '11. 자금, 43. OIS스왑, 44. 이자율옵션' 중 원화 거래인 경우 및 '41. 이자율스왑(원화)' 등)는 기준통화코드와 상대통화코드에 모두 원화(KRW)를 입력
A22: 16 | B22: 상대통화코드 | C22: J열 | D22: 3자리 | E22: [FX SWAP, ND SWAP, SPOT MAR, NDF, DF, ND MAR] "KRW" 디폴트 [DEPOSIT] CCY pair 있는 그대로 사용 [IRS, ND IRS, CRS, ND CRS, FRA, ND FRA, SWAPTION] CCY pair 뒤에서 3자리 (없는 경우 앞 3자리 사용) | G22: X(3) | H22: 3 | I22: M | J22: N | K22: (CODE 18)
A23: 17 | B23: 체결시각 | C23: K열 | D23: HHMMSS | E23: FX.IRS 딜 조회 승인화면 DEAL ALL 내역상 "DEAL TIME" | G23: X(6) | H23: 6 | I23: M | J23: N | L23: HHMMSS
A24: 18 | B24: 장내외구분코드 | C24: L열 | D24: 1 | E24: "1" 로 디폴트 | G24: X(1) | H24: 1 | I24: M | J24: N | K24: (CODE 314) | L24: 1:장외, 2:장내
A25: 19 | B25: 결제일자 | C25: M열 | D25: YYYYMMDD | E25: SPOT MAR, DF, NDF, ND MAR 상품만 FX 딜조회승인화면_DEAL ALL 내역_FAR DATE | G25: X(8) | H25: 8 | I25: O | J25: N | L25: YYYYMMDD 【보고대상 상품: 21. 현물환, 22. Average Price FX, 31. 통화선도(차액결제제외), 32. 통화선도(차액결제)】
A26: 20 | B26: 시작일자 | C26: N열 | D26: YYYYMMDD | E26: [FX SWAP, ND SWAP, DEPOSIT] 상품만 FX 딜조회승인화면_DEAL ALL 내역_NEAR DATE [IRS, ND IRS, CRS, ND CRS, FRA, ND FRA] IRS 딜조회승인화면_DEAL ALL 내역_VALUE DATE | G26: X(8) | H26: 8 | I26: O | J26: N | L26: YYYYMMDD 【보고대상 상품: 11. 자금, 33. 외환스왑(차액결제제외), 34. 외환스왑(차액결제), 35. 통화스왑(차액결제제외), 36. 통화스왑(차액결제), 41. 이자율스왑(원화), 42. 이자율스왑(외화), 43. OIS스왑, 45. FRA】 ■ '33. 외환스왑(차액결제제외), 34. 외환스왑(차액결제)'의 경우 Near Value Date 입력 ■ '35. 통화스왑(차액결제제외), 36. 통화스왑(차액결제), 41. 이자율스왑(원화), 42. 이자율스왑(외화)'의 경우 스왑개시일(Effecetive date) 입력
A27: 21 | B27: 종료일자 | C27: O열 | D27: YYYYMMDD | E27: [FX SWAP, ND SWAP, DEPOSIT] 상품만 FX 딜조회승인화면_DEAL ALL 내역_FAR DATE [IRS, ND IRS, CRS, ND CRS, FRA, ND FRA] IRS 딜조회승인화면_DEAL ALL 내역_MATURITY DATE | G27: X(8) | H27: 8 | I27: O | J27: N | L27: YYYYMMDD 【보고대상 상품: 11. 자금, 33. 외환스왑(차액결제제외), 34. 외환스왑(차액결제), 35. 통화스왑(차액결제제외), 36. 통화스왑(차액결제), 41. 이자율스왑(원화), 42. 이자율스왑(외화), 43. OIS스왑, 45. FRA】 ■ '33. 외환스왑(차액결제제외), 34. 외환스왑(차액결제)'의 경우 Far Value Date 입력
A28: 22 | B28: 행사만기일자 | C28: P열 | D28: YYYYMMDD | E28: [SWAPTION] 상품만 IRS 딜조회승인화면_DEAL ALL 내역_MATURITY DATE | G28: X(8) | H28: 8 | I28: O | J28: N | L28: YYYYMMDD 【보고대상 상품: 37. 통화옵션, 44. 이자율옵션】
A29: 23 | B29: 기일코드 | C29: Q열 | D29: 2자리 | E29: [DEPOSIT, DF, NDF, ND MAR, FX SWAP, ND SWAP] 상품만 FX 딜조회승인화면_DEAL ALL 내역_TENOR 기준으로 고유코드 기입 | G29: X(2) | H29: 2 | I29: O | J29: N | K29: (CODE 409) | L29: 【보고대상 상품: 11. 자금, 21. 현물환, 31. 통화선도(차액결제제외), 32. 통화선도(차액결제), 33. 외환스왑(차액결제제외), 34. 외환스왑(차액결제)】 예: overnight, 1월물, 1*3월물, odd date
A30: 24 | B30: 거래환율 | C30: R열 | E30: [SPOT MAR, DF, NDF, ND MAR] 상품만 FX 딜조회승인화면_DEAL ALL 내역_FAR RATE [CRS, ND CRS] 상품만 IRS 딜조회승인화면_DEAL ALL 내역_EXCH RATE | G30: S9(11,6) | H30: 12 | I30: O | J30: N | L30: 기준통화 1단위당 상대통화 【보고대상 상품: 21. 현물환, 22. Average Price FX, 31. 통화선도(차액결제제외), 32. 통화선도(차액결제), 35. 통화스왑(차액결제제외), 36. 통화스왑(차액결제), 37. 통화옵션】 ■ '22. Average Price FX'의 경우 실제 거래된 환율 ■ '35. 통화스왑(차액결제제외), 36. 통화스왑(차액결제)'의 경우 명목원금교환에 적용된 환율 ■ '37. 통화옵션'의 경우 옵션 행사환율
A31: 25 | B31: 근일물거래환율 | C31: S열 | E31: [FX SWAP, ND SWAP] 상품만 FX 딜조회승인화면_DEAL ALL 내역_NEAR RATE | G31: S9(11,6) | H31: 12 | I31: O | J31: N | L31: 기준통화 1단위당 상대통화 【보고대상 상품: '33. 외환스왑(차액결제제외), 34. 외환스왑(차액결제)】
A32: 26 | B32: 원일물거래환율 | C32: T열 | E32: [FX SWAP, ND SWAP] 상품만 FX 딜조회승인화면_DEAL ALL 내역_FAR RATE | G32: S9(11,6) | H32: 12 | I32: O | J32: N | L32: 기준통화 1단위당 상대통화 【보고대상 상품: '33. 외환스왑(차액결제제외), 34. 외환스왑(차액결제)】
A33: 27 | B33: 시장평균환율대비가감율 | C33: U열 | E33: [SPOT MAR] 상품만 FX 딜조회승인화면_DEAL ALL 내역_MARGIN | G33: S9(11,6) | H33: 12 | I33: O | J33: N | L33: 단위:원 【보고대상 상품: '22. Average Price FX】
A34: 28 | B34: 고정금리 | C34: V열 | E34: [DEPOSIT] 상품만 FX 딜조회승인화면_DEAL ALL 내역_NEAR RATE [IRS, ND IRS, CRS, ND CRS, FRA, ND FRA,SWAPTION] 상품만 IRS 딜조회승인화면_DEAL ALL 내역_RATE | G34: S9(11,6) | H34: 12 | I34: O | J34: N | K34: (CODE 2351) | L34: 【보고대상 상품: '11. 자금, 35. 통화스왑(차액결제제외), 36. 통화스왑(차액결제), 41. 이자율스왑(원화), 42. 이자율스왑(외화), 43. OIS스왑, 44. 이자율옵션, 45. FRA】 ■ '44. 이자율옵션'의 경우 행사금리
A35: 29 | B35: 중개사거래변동금리구분코드 | C35: W열 | D35: 2자리 | E35: [IRS, ND IRS, CRS, ND CRS, FRA, ND FRA] 상품만 IRS 딜조회승인화면_DEAL ALL 내역_INDEX 기준으로 고유코드 기입 | G35: X(2) | H35: 2 | I35: O | J35: N | K35: CODE 추가 (2:중개사 거래 변동금리 구분) *추가 불가능할 경우 CODE77 사용 | L35: 1: LIBOR, 2: EURIBOR, 3: CD금리, 4. EURO-LIBOR, 5. SIBOR, 6. TIBOR, 7. HIBOR, 9. 기타 【보고대상 상품: '35. 통화스왑(차액결제제외), 36. 통화스왑(차액결제), 41. 이자율스왑(원화), 42. 이자율스왑(외화), 45. FRA】
A36: 30 | B36: 변동금리 | C36: X열 | D36: 0 | E36: [IRS, ND IRS, CRS, ND CRS, FRA, ND FRA] 상품만 "0" 값 디폴트 | G36: S9(11,6) | H36: 12 | I36: O | J36: N | K36: (CODE 328) | L36: 【보고대상 상품: '35. 통화스왑(차액결제제외), 36. 통화스왑(차액결제), 41. 이자율스왑(원화), 42. 이자율스왑(외화), 45. FRA】
A37: 31 | B37: 콜풋옵션구분코드 | C37: X | D37: X | E37: X | G37: X(1) | H37: 1 | I37: O | J37: N | K37: (CODE 83) | L37: 1: Call Option, 2: Put Option 【보고대상 상품: 37. 통화옵션】
A38: 32 | B38: 옵션형태구분코드 | C38: X | D38: X | E38: X | G38: X(1) | H38: 1 | I38: O | J38: N | L38: 1: American Option, 2: European Option 【보고대상 상품: 37. 통화옵션】
A39: 33 | B39: USD옵션금액 | C39: X | D39: X | E39: X | G39: S9(15,2) | H39: 16 | I39: O | J39: N | L39: 【보고대상 상품: 37. 통화옵션】
A41: <작성시 유의사항>
...

Sheet FX_DEAL All
A1: DEAL NO | B1: SEQ | C1: STATUS | D1: TRADE DATE | E1: REFERENCE NO | F1: BUYER(LEND) | G1: SELLER(BORROW) | H1: PRODUCT | I1: TENOR | J1: AMOUNT | K1: MARGIN(TERM) | L1: NEAR RATE(RATE) | M1: FAR RATE(INTEREST) | N1: NEAR DATE | O1: FAR DATE | P1: CCY PAIR | Q1: B BRO CCY | R1: B BRO. | S1: S BRO CCY | T1: S BRO. | U1: B TRADER | V1: S TRADER | W1: B BROKER | X1: S BROKER | Y1: DEAL TIME | Z1: NEAR FIXING | AA1: NEAR MAR | AB1: FAR FIXING | AC1: FAR MAR | AD1: AMENDMENT USER | AE1: AMENDMENT TIME | AF1: PDF 출력 구분1 | AG1: PDF 출력 구분2 | AH1: B VIA | AI1: S VIA | AJ1: B.SETTLE | AK1: S.SETTLE | AL1: BUYER NOTES | AM1: SELLER NOTES | AN1: B CNFM BRO | AO1: B CNFM TIME | AP1: S CNFM BRO | AQ1: S CNFM TIME | AR1: DEAL 입력정보 | AS1: DEAL 입력번호
A2: 1 | B2: 1 | C2: P | D2: 45408 | E2: 2024042600107 | F2: KB SEL | G2: SHB HKG | H2: DEPOSIT | I2: 1M | J2: 45000000 | K2: 31 | L2: 2.92 | M2: 113150 | N2: 45401 | O2: 45432 | P2: AUD | Q2: KRW | R2: 692772 | S2: USD | T2: 248.25 | U2: 안준영 | V2: Irus Wong | Y2: 164043 | AF2: 1.Yes | AG2: 1.Yes | AJ2: ANZ MELBOURNE(ANZBAU3M) A/C 816686AUD00001 (CZNBKRSE) | AK2: COMMONWEALTH BANK OF AUSTRALIA SYDNEY(CTBAAU2SXXX) A/C 06796710003886(SHBKHKHX) | AR2: 직접입력
A3: 2 | B3: 1 | C3: P | D3: 45408 | E3: 2024042600207 | F3: SHB HKG | G3: KB SEL | H3: DEPOSIT | I3: ODD | J3: 70000000 | K3: 93 | L3: 2.1 | M3: 379750 | N3: 45401 | O3: 45494 | P3: CAD | Q3: KRW | R3: 3650656 | S3: KRW | T3: 3555321 | U3: 안준영 | V3: 황윤미 | Y3: 164320 | AF3: 1.Yes | AG3: 1.Yes | AJ3: TO BE ADVISED DIRECT | AK3: TO BE ADVISED DIRECT | AR3: 직접입력
A4: 3 | B4: 1 | C4: P | D4: 45408 | E4: 2024042600307 | F4: CCB SEL | G4: DGB SEL | H4: DEPOSIT | I4: O/N | J4: 1500000000 | K4: 1 | L4: 2.2255 | M4: 30909.72 | N4: 45385 | O4: 45386 | P4: CNH | Q4: KRW | R4: 51701 | S4: KRW | T4: 0 | U4: 최주현 | V4: BOCOM SEL | Y4: 144645 | AF4: 1.Yes | AG4: 1.Yes | AI4: TRADITION CHN | AJ4: BOC HKG (BKCHHKHH838) FOR BOC SEL (BKCHKRSE) IN FAVOR OF PUSBKR2PINT A/C 100000200177706 | AK4: BANK OF CHINA HK CLEARING CENTRE (BKCHHKHH838) A/C 01287560119126 (COMMKRSEXXX) | AR4: 직접입력
A5: 4 | B5: 1 | C5: P | D5: 45408 | E5: 2024042600407 | F5: DGB SEL | G5: CCB HKG | H5: DEPOSIT | I5: 2M | J5: 18000000 | K5: 62 | L5: -0.12 | M5: -2066.66 | N5: 45401 | O5: 45463 | P5: EUR | Q5: USD | R5: 365.81 | S5: KRW | T5: 255209 | U5: 김정경 | V5: 자금부 | Y5: 171340 | AF5: 1.Yes | AG5: 1.Yes | AJ5: LLOYDS BANK LDN(LOYDGB2L) A/C 59003866(HVBKGB2L) | AK5: CHINA CONSTRUCTION BANK FRANKFURT(PCBCDEFF) A/C 15-00-110028 (PCBCKRSE) | AR5: 직접입력
A6: 5 | B6: 1 | C6: P | D6: 45408 | E6: 2024042600507 | F6: IBK SEL | G6: BNP SEL | H6: DEPOSIT | I6: O/N | J6: 52000000 | K6: 1 | L6: 0.15 | M6: 45.21 | N6: 45399 | O6: 45400 | P6: GBP | Q6: KRW | R6: 10439 | S6: KRW | T6: 5093 | U6: 안준영 | V6: 정지혜 | Y6: 172121 | AF6: 1.Yes | AG6: 1.Yes | AJ6: TO BE ADVISED DIRECT | AK6: TO BE ADVISED DIRECT | AR6: 직접입력
A7: 6 | B7: 1 | C7: P | D7: 45408 | E7: 2024042600607 | F7: BNP PAR | G7: IBK HKG | H7: DEPOSIT | I7: O/N | J7: 17500000 | K7: 1 | L7: 0.15 | M7: 71.92 | N7: 45399 | O7: 45400 | P7: HKD | Q7: USD | R7: 0.61 | S7: KRW | T7: 1706 | U7: Cindy Chung | V7: 안준영 | Y7: 172708 | AF7: 1.Yes | AG7: 1.Yes | AJ7: TO BE ADVISED DIRECT | AK7: TO BE ADVISED DIRECT | AR7: 직접입력
A8: 7 | B8: 1 | C8: P | D8: 45408 | E8: 2024042600707 | F8: CS SEL | G8: SG SEL | H8: DEPOSIT | I8: O/N | J8: 3000000000 | K8: 1 | L8: 0.15 | M8: 416 | N8: 45399 | O8: 45400 | P8: JPY | Q8: KRW | R8: 0 | S8: KRW | T8: 246 | U8: CIMB KUL | V8: 정지혜 | Y8: 174556 | AF8: 1.Yes | AG8: 1.Yes | AH8: TULLETT HKG | AJ8: TO BE ADVISED DIRECT | AK8: TO BE ADVISED DIRECT | AR8: 직접입력
A9: 8 | B9: 1 | C9: P | D9: 45408 | E9: 2024042600807 | F9: SG PAR | G9: CS SGP | H9: DEPOSIT | I9: O/N | J9: 20000000 | K9: 1 | L9: 2.5 | M9: 138.89 | N9: 45399 | O9: 45400 | P9: NZD | Q9: KRW | R9: 452 | S9: KRW | T9: 912 | U9: 신문경 | V9: 안준영 | Y9: 174749 | AF9: 1.Yes | AG9: 1.Yes | AJ9: TO BE ADVISED DIRECT | AK9: TO BE ADVISED DIRECT | AR9: 직접입력
A10: 9 | B10: 1 | C10: P | D10: 45408 | E10: 2024042600907 | F10: KB SEL | G10: DGB SEL | H10: DEPOSIT | I10: S/N | J10: 35000000 | K10: 3 | L10: 1.1 | M10: 27.12 | N10: 45401 | O10: 45404 | P10: SGD | Q10: KRW | R10: 238 | S10: KRW | T10: 0 | U10: 정지혜 | V10: CIMB KUL | Y10: 180536 | AF10: 1.Yes | AG10: 1.Yes | AI10: TULLETT HKG | AJ10: TO BE ADVISED DIRECT | AK10: TO BE ADVISED DIRECT | AR10: 직접입력
A11: 10 | B11: 1 | C11: P | D11: 45408 | E11: 2024042601007 | F11: DGB SEL | G11: KB SGP | H11: DEPOSIT | I11: O/N | J11: 100000000 | K11: 1 | L11: 5.6 | M11: 4666666.7 | N11: 45385 | O11: 45386 | P11: USD | Q11: USD | R11: 8333.33 | S11: KRW | T11: 22178324 | U11: Cindy Chung | V11: 황윤미 | Y11: 111618 | AF11: 1.Yes | AG11: 1.Yes | AJ11: JP MORGAN CHASE NYK(CHASUS33) A/C 780-2-54611(HVBKSGSG) | AK11: BANK OF NEW YORK MELLON NYK(IRVTUS3N) A/C 890-1324-728(EVERKRSEXXX) | AR11: 직접입력
A12: 11 | B12: 1 | C12: P | D12: 45408 | E12: 2024042600105 | F12: SG SEL | G12: BNP SEL | H12: DF | I12: 3M | J12: 50000000 | K12: 0 | L12: 0 | M12: 1356.1 | O12: 45488 | P12: USD/KRW | Q12: KRW | R12: 0 | S12: KRW | T12: 0 | U12: 김예슬 | V12: 장원준 | Y12: 103555 | AF12: 1.Yes | AG12: 1.Yes | AJ12: TO BE ADVISED DIRECT | AK12: TO BE ADVISED DIRECT | AR12: 직접입력
A13: 13 | B13: 3 | C13: P | D13: 45408 | E13: 2024042600301 | F13: BNP SEL | G13: SG SEL | H13: FX SWAP | I13: 2*3 | J13: 1.1122233e+08 | K13: -2.1233 | L13: 1348.5555 | M13: 1346.4322 | N13: 45447 | O13: 45478 | P13: USD/KRW | Q13: KRW | R13: 889760 | S13: KRW | T13: 1445860 | U13: 장유성 | V13: 민선희 | Y13: 174140 | AF13: 1.Yes | AG13: 1.Yes | AJ13: TO BE ADVISED DIRECT | AK13: TO BE ADVISED DIRECT | AL13: ㅇㅇㅇㅇ | AR13: 직접입력
A14: 15 | B14: 1 | C14: P | D14: 45408 | E14: 2024042601101 | F14: CS SEL | G14: KB SEL | H14: FX SWAP | I14: 1M | J14: 100000000000 | K14: -2.2222 | L14: 1325.3333 | M14: 1323.1111 | N14: 45387 | O14: 45419 | P14: KRW/USD | Q14: KRW | R14: 200000 | S14: KRW | T14: 100000 | U14: 최원 | V14: 이현직 | Y14: 180639 | AF14: 1.Yes | AG14: 1.Yes | AJ14: TO BE ADVISED DIRECT | AK14: TO BE ADVISED DIRECT | AL14: ㅇㅇㅇ | AM14: ㅇㅇㅇ | AR14: 직접입력
A15: 16 | B15: 1 | C15: P | D15: 45408 | E15: 2024042601201 | F15: KB SEL | G15: CS SEL | H15: FX SWAP | I15: 1M | J15: 88000000 | K15: -2.1 | L15: 1325.3333 | M15: 1323.1111 | N15: 45387 | O15: 45419 | P15: EUR/KRW | Q15: KRW | R15: 200000 | S15: KRW | T15: 100000 | U15: 최원 | V15: 이현직 | Y15: 180639 | AF15: 1.Yes | AG15: 1.Yes | AJ15: TO BE ADVISED DIRECT | AK15: TO BE ADVISED DIRECT | AL15: ㅇㅇㅇ | AM15: ㅇㅇㅇ | AR15: 직접입력
A16: 17 | B16: 1 | C16: P | D16: 45408 | E16: 2024042601301 | F16: SG SEL | G16: CCB SEL | H16: FX SWAP | I16: 1M | J16: 54000000 | K16: -0.065 | L16: 1325.3333 | M16: 1323.1111 | N16: 45387 | O16: 45419 | P16: GBP/KRW | Q16: KRW | R16: 200000 | S16: KRW | T16: 100000 | U16: 최원 | V16: 이현직 | Y16: 180639 | AF16: 1.Yes | AG16: 1.Yes | AJ16: TO BE ADVISED DIRECT | AK16: TO BE ADVISED DIRECT | AL16: ㅇㅇㅇ | AM16: ㅇㅇㅇ | AR16: 직접입력
A17: 18 | B17: 1 | C17: P | D17: 45408 | E17: 2024042601401 | F17: CCB SEL | G17: SG SEL | H17: FX SWAP | I17: 1M | J17: 100000000 | K17: -0.01 | L17: 1325.3333 | M17: 1323.1111 | N17: 45387 | O17: 45419 | P17: HKD/KRW | Q17: KRW | R17: 200000 | S17: KRW | T17: 100000 | U17: 최원 | V17: 이현직 | Y17: 180639 | AF17: 1.Yes | AG17: 1.Yes | AJ17: TO BE ADVISED DIRECT | AK17: TO BE ADVISED DIRECT | AL17: ㅇㅇㅇ | AM17: ㅇㅇㅇ | AR17: 직접입력
A18: 19 | B18: 1 | C18: P | D18: 45408 | E18: 2024042601501 | F18: IBK SEL | G18: DGB SEL | H18: FX SWAP | I18: 1M | J18: 20000000000 | K18: -0.05 | L18: 1325.3333 | M18: 1323.1111 | N18: 45387 | O18: 45419 | P18: CNH/KRW | Q18: KRW | R18: 200000 | S18: KRW | T18: 100000 | U18: 최원 | V18: 이현직 | Y18: 180639 | AF18: 1.Yes | AG18: 1.Yes | AJ18: TO BE ADVISED DIRECT | AK18: TO BE ADVISED DIRECT | AL18: ㅇㅇㅇ | AM18: ㅇㅇㅇ | AR18: 직접입력
A19: 20 | B19: 1 | C19: P | D19: 45408 | E19: 2024042601161 | F19: DGB SEL | G19: IBK SEL | H19: FX SWAP | I19: 1M | J19: 3000000000 | K19: 0.01 | L19: 1325.3333 | M19: 1323.1111 | N19: 45387 | O19: 45419 | P19: JPY/KRW | Q19: KRW | R19: 200000 | S19: KRW | T19: 100000 | U19: 최원 | V19: 이현직 | Y19: 180639 | AF19: 1.Yes | AG19: 1.Yes | AJ19: TO BE ADVISED DIRECT | AK19: TO BE ADVISED DIRECT | AL19: ㅇㅇㅇ | AM19: ㅇㅇㅇ | AR19: 직접입력
A20: 31 | B20: 1 | C20: P | D20: 45408 | E20: 2024042600104 | F20: BNP PAR | G20: SG PAR | H20: NDF | I20: 3M | J20: 50000000 | K20: 0 | L20: 0 | M20: 1356.2 | O20: 45488 | P20: USD/KRW | Q20: KRW | R20: 400000 | S20: KRW | T20: 846500 | U20: 장원준 | V20: 김예슬 | Y20: 103646 | AB20: 45485 | AC20: 45484 | AF20: 1.Yes | AG20: 1.Yes | AJ20: TO BE ADVISED DIRECT | AK20: TO BE ADVISED DIRECT | AR20: 직접입력
A21: 34 | B21: 1 | C21: P | D21: 45408 | E21: 2024042600106 | F21: SG SEL | G21: BNP SEL | H21: ND MAR | I21: 1M | J21: 1.1122233e+08 | K21: 27.4321 | L21: 0 | M21: 1328.3209 | O21: 45429 | P21: USD/KRW | Q21: KRW | R21: 778540 | S21: KRW | T21: 1334640 | U21: 장유성 | V21: 윤나라 | Y21: 152146 | AB21: 45428 | AC21: 45426 | AF21: 1.Yes | AG21: 1.Yes | AJ21: TO BE ADVISED DIRECT | AK21: TO BE ADVISED DIRECT | AR21: 직접입력
A22: 35 | B22: 1 | C22: P | D22: 45408 | E22: 2024042600102 | F22: BNP SEL | G22: KB SEL | H22: ND SWAP | I22: 1*4 | J22: 1e+08 | K22: -0.1111 | L22: 1312.5555 | M22: 1312.4444 | N22: 45419 | O22: 45509 | P22: USD/KRW | Q22: KRW | R22: 800000 | S22: KRW | T22: 1200000 | U22: 장유성 | V22: 윤나라 | Y22: 145455 | Z22: 45415 | AA22: 45414 | AB22: 45506 | AC22: 45505 | AF22: 1.Yes | AG22: 1.Yes | AJ22: TO BE ADVISED DIRECT | AK22: TO BE ADVISED DIRECT | AR22: 직접입력
A23: 37 | B23: 1 | C23: P | D23: 45408 | E23: 2024042600103 | F23: KB SEL | G23: BNP SEL | H23: SPOT MAR | I23: SPOT | J23: 1250000.2 | K23: -0.125 | L23: 1352.9 | M23: 1352.775 | O23: 45387 | P23: USD/KRW | Q23: KRW | R23: 7500 | S23: KRW | T23: 3750 | U23: 윤나라 | V23: 장유성 | Y23: 145610 | AF23: 1.Yes | AG23: 1.Yes | AJ23: TO BE ADVISED DIRECT | AK23: TO BE ADVISED DIRECT | AR23: 직접입력
A24: 39 | B24: 1 | C24: P | D24: 45408 | E24: 2024042600303 | F24: CS SEL | G24: IBK SEL | H24: SPOT MAR | I24: SPOT | J24: 50000000 | K24: 0 | L24: 1363.7 | M24: 1363.7 | O24: 45393 | P24: USD/KRW | Q24: KRW | R24: 300000 | S24: KRW | T24: 300000 | U24: 강찬용 | V24: 유탁균 | Y24: 171509 | AF24: 1.Yes | AG24: 1.Yes | AJ24: TO BE ADVISED DIRECT | AK24: TO BE ADVISED DIRECT | AN24: 이종민 | AO24: 0.71884259 | AP24: 이종민 | AQ24: 0.71885417 | AR24: 체결Confirm | AS24: 45413
A25: 40 | B25: 1 | C25: P | D25: 45408 | E25: 2024042601103 | F25: IBK SEL | G25: CS SEL | H25: SPOT MAR | I25: SPOT | J25: 5000000 | K25: 0.05 | L25: 1363.7 | M25: 1363.75 | O25: 45397 | P25: USD/KRW | Q25: KRW | R25: 30000 | S25: KRW | T25: 30000 | U25: 조가영 | V25: 이상민 | Y25: 104023 | AF25: 1.Yes | AG25: 1.Yes | AJ25: TO BE ADVISED DIRECT | AK25: TO BE ADVISED DIRECT | AR25: 직접입력

Sheet IRS_DEAL All
A1: DEAL NO | B1: SEQ | C1: STATUS | D1: TRADE DATE | E1: REFERENCE NO | F1: PAY | G1: RECEIVE | H1: PRODUCT | I1: TENOR | J1: CCY PAIR | K1: AMOUNT | L1: RATE | M1: VALUE DATE | N1: MATURITY DATE | O1: PAY BRO CCY | P1: PAY BRO. | Q1: REC BRO CCY | R1: REC BRO. | S1: PAY TRADER | T1: REC TRADER | U1: PAY BROKER | V1: REC BROKER. | W1: EXCH RATE | X1: BREAK CLAUSE YEARS | Y1: BREAK FREQUENCY | Z1: BREAK CLAUSE DATE | AA1: DEAL TIME | AB1: PAY MARKETWIRE ID | AC1: REC MARKETWIRE ID | AD1: BUYER NOTES | AE1: SELLER NOTES | AF1: AMENDMENT USER | AG1: AMENDMENT TIME | AH1: FLOATING | AI1: INDEX | AJ1: EXEL NO | AK1: EXEL TIME
A2: 1 | B2: 1 | C2: P | D2: 45408 | E2: 2024042500133 | F2: KB SEL | G2: DGB SEL | H2: CRS | I2: 15Y | J2: USD/KRW | K2: 23000000 | L2: 2.88525 | M2: 45411 | N2: 50889 | O2: KRW | P2: 394190 | Q2: KRW | R2: 315360 | S2: DG마킷 | T2: 노마킷 | U2: 한국금융아이티1 | W2: 1301.02 | AA2: 124425 | AH2: 3 | AI2: SOFR
A3: 1 | B3: 1 | C3: P | D3: 45408 | E3: 2024042500155 | F3: DGB SEL | G3: KB SEL | H3: FRA | J3: KRW | K3: 20000000000 | L3: 3.05 | M3: 45407 | N3: 46503 | O3: KRW | P3: 0 | Q3: USD | R3: 0 | S3: 강진영 | T3: 전영애 | W3: 0 | AA3: 131700 | AH3: 3 | AI3: CD
A4: 1 | B4: 3 | C4: P | D4: 45408 | E4: 2024042500111 | F4: IBK SEL | G4: BNP SEL | H4: IRS | I4: 3Y | J4: KRW | K4: 50000000000 | L4: 3.53 | M4: 45408 | N4: 46503 | O4: KRW | P4: 396868 | Q4: KRW | R4: 850431 | S4: 테스트 영애 | T4: 강진영 | W4: 0 | AA4: 92744 | AD4: THE TRADE IS CLEARED VIA : KOREA EXCHANGE(KRX) CLEARING | AE4: THE TRADE IS CLEARED VIA : KOREA EXCHANGE(KRX) CLEARING | AF4: jykang | AG4: 20240425082626 | AH4: 3 | AI4: CD
A5: 2 | B5: 3 | C5: P | D5: 45408 | E5: 2024042501211 | F5: BNP SEL | G5: IBK SEL | H5: IRS | I5: 3Y | J5: USD | K5: 20000000 | L5: 3.53 | M5: 45408 | N5: 46503 | O5: KRW | P5: 396868 | Q5: KRW | R5: 850431 | S5: 테스트 영애 | T5: 강진영 | W5: 0 | AA5: 92708 | AD5: THE TRADE IS CLEARED VIA : KOREA EXCHANGE(KRX) CLEARING | AE5: THE TRADE IS CLEARED VIA : KOREA EXCHANGE(KRX) CLEARING | AF5: jykang | AG5: 20240425082626 | AH5: 3 | AI5: SOFR Term Rate
A6: 1 | B6: 1 | C6: P | D6: 45408 | E6: 2024042500144 | F6: CS SGP | G6: IBK HKG | H6: ND CRS | I6: 3Y | J6: USD/KRW | K6: 10000000 | L6: 2.78 | M6: 45411 | N6: 46506 | O6: USD | P6: 286.87 | Q6: KRW | R6: 589524 | S6: 전영애 | T6: 강진영 | W6: 1387 | AA6: 122211 | AH6: 3 | AI6: SOFR
A7: 1 | B7: 1 | C7: P | D7: 45408 | E7: 2024042500266 | F7: IBK HKG | G7: CS SEL | H7: ND FRA | J7: USD | K7: 50000000 | L7: 3.05 | M7: 45407 | N7: 46503 | O7: KRW | P7: 0 | Q7: USD | R7: 0 | S7: 강진영 | T7: 전영애 | W7: 0 | AA7: 133003 | AH7: 3 | AI7: SOFR Term Rate
A8: 1 | B8: 1 | C8: P | D8: 45408 | E8: 2024042500422 | F8: SHB HKG | G8: SG PAR | H8: ND IRS | I8: 12Y | J8: KRW | K8: 15000000000 | L8: 2.9875 | M8: 45408 | N8: 49793 | O8: KRW | P8: 117172 | Q8: KRW | R8: 62491 | S8: 송윤옥 | T8: 노마킷 | V8: 한국금융아이티1 | W8: 0 | AA8: 125502 | AD8: THE TRADE IS CLEARED VIA : LCH.CLEARNET LIMITED CLEARING | AE8: THE TRADE IS CLEARED VIA : LCH.CLEARNET LIMITED CLEARING | AH8: 3 | AI8: CD
A9: 1 | B9: 1 | C9: P | D9: 45408 | E9: 2024042500177 | F9: SG SEL | G9: SHB SEL | H9: SWAPTION | J9: KRW | K9: 20000000000 | L9: 2.9 | M9: 45408 | N9: 46503 | O9: USD | P9: 414.03 | Q9: KRW | R9: 850835 | S9: 전영애 | T9: 강진영 | W9: 0 | AA9: 105001 | AB9: TEST3 | AC9: TEST3 | AD9: THE TRADE IS CLEARED VIA : LCH.CLEARNET LIMITED CLEARING | AE9: THE TRADE IS CLEARED VIA : LCH.CLEARNET LIMITED CLEARING
A10: 2 | B10: 1 | C10: P | D10: 45408 | E10: 2024042500277 | F10: SHB SEL | G10: SG SEL | H10: SWAPTION | J10: USD | K10: 35000000 | L10: 2.9 | M10: 45408 | N10: 46503 | O10: USD | P10: 414.03 | Q10: KRW | R10: 850835 | S10: 전영애 | T10: 강진영 | W10: 0 | AA10: 105033 | AD10: THE TRADE IS CLEARED VIA : LCH.CLEARNET LIMITED CLEARING | AE10: THE TRADE IS CLEARED VIA : LCH.CLEARNET LIMITED CLEARING
